Traceback (most recent call last):
  File "/opt/hostedtoolcache/Python/3.11.11/x64/lib/python3.11/site-packages/jupyter_cache/executors/utils.py", line 58, in single_nb_execution
    executenb(
  File "/opt/hostedtoolcache/Python/3.11.11/x64/lib/python3.11/site-packages/nbclient/client.py", line 1319, in execute
    return NotebookClient(nb=nb, resources=resources, km=km, **kwargs).execute()
           ^^^^^^^^^^^^^^^^^^^^^^^^^^^^^^^^^^^^^^^^^^^^^^^^^^^^^^^^^^^^^^^^^^^^^
  File "/opt/hostedtoolcache/Python/3.11.11/x64/lib/python3.11/site-packages/jupyter_core/utils/__init__.py", line 165, in wrapped
    return loop.run_until_complete(inner)
           ^^^^^^^^^^^^^^^^^^^^^^^^^^^^^^
  File "/opt/hostedtoolcache/Python/3.11.11/x64/lib/python3.11/asyncio/base_events.py", line 654, in run_until_complete
    return future.result()
           ^^^^^^^^^^^^^^^
  File "/opt/hostedtoolcache/Python/3.11.11/x64/lib/python3.11/site-packages/nbclient/client.py", line 709, in async_execute
    await self.async_execute_cell(
  File "/opt/hostedtoolcache/Python/3.11.11/x64/lib/python3.11/site-packages/nbclient/client.py", line 1062, in async_execute_cell
    await self._check_raise_for_error(cell, cell_index, exec_reply)
  File "/opt/hostedtoolcache/Python/3.11.11/x64/lib/python3.11/site-packages/nbclient/client.py", line 918, in _check_raise_for_error
    raise CellExecutionError.from_cell_and_msg(cell, exec_reply_content)
nbclient.exceptions.CellExecutionError: An error occurred while executing the following cell:
------------------
# Generate data
input, input_with_bias, output = generate_dataset()
------------------


[0;31m---------------------------------------------------------------------------[0m
[0;31mAttributeError[0m                            Traceback (most recent call last)
Cell [0;32mIn[5], line 2[0m
[1;32m      1[0m [38;5;66;03m# Generate data[39;00m
[0;32m----> 2[0m [38;5;28minput[39m, input_with_bias, output [38;5;241m=[39m [43mgenerate_dataset[49m[43m([49m[43m)[49m

Cell [0;32mIn[4], line 25[0m, in [0;36mgenerate_dataset[0;34m(num_points, shuffle, key)[0m
[1;32m     23[0m [38;5;66;03m# Shuffle[39;00m
[1;32m     24[0m [38;5;28;01mif[39;00m shuffle:
[0;32m---> 25[0m     idx [38;5;241m=[39m [43mjr[49m[38;5;241;43m.[39;49m[43mshuffle[49m(key2, jnp[38;5;241m.[39marange(num_points))
[1;32m     26[0m     [38;5;28minput[39m, input_with_bias, output [38;5;241m=[39m [38;5;28minput[39m[idx], input_with_bias[idx], output[idx]
[1;32m     28[0m [38;5;28;01mreturn[39;00m [38;5;28minput[39m, input_with_bias, output

[0;31mAttributeError[0m: module 'jax.random' has no attribute 'shuffle'

