Traceback (most recent call last):
  File "/opt/hostedtoolcache/Python/3.9.15/x64/lib/python3.9/site-packages/jupyter_cache/executors/utils.py", line 58, in single_nb_execution
    executenb(
  File "/opt/hostedtoolcache/Python/3.9.15/x64/lib/python3.9/site-packages/nbclient/client.py", line 1204, in execute
    return NotebookClient(nb=nb, resources=resources, km=km, **kwargs).execute()
  File "/opt/hostedtoolcache/Python/3.9.15/x64/lib/python3.9/site-packages/nbclient/util.py", line 84, in wrapped
    return just_run(coro(*args, **kwargs))
  File "/opt/hostedtoolcache/Python/3.9.15/x64/lib/python3.9/site-packages/nbclient/util.py", line 62, in just_run
    return loop.run_until_complete(coro)
  File "/opt/hostedtoolcache/Python/3.9.15/x64/lib/python3.9/asyncio/base_events.py", line 647, in run_until_complete
    return future.result()
  File "/opt/hostedtoolcache/Python/3.9.15/x64/lib/python3.9/site-packages/nbclient/client.py", line 663, in async_execute
    await self.async_execute_cell(
  File "/opt/hostedtoolcache/Python/3.9.15/x64/lib/python3.9/site-packages/nbclient/client.py", line 965, in async_execute_cell
    await self._check_raise_for_error(cell, cell_index, exec_reply)
  File "/opt/hostedtoolcache/Python/3.9.15/x64/lib/python3.9/site-packages/nbclient/client.py", line 862, in _check_raise_for_error
    raise CellExecutionError.from_cell_and_msg(cell, exec_reply_content)
nbclient.exceptions.CellExecutionError: An error occurred while executing the following cell:
------------------
try:
    import dynamax
except ModuleNotFoundError:
    print('installing dynamax')
    %pip install -qq dynamax
    import dynamax


------------------

[0;31m---------------------------------------------------------------------------[0m
[0;31mModuleNotFoundError[0m                       Traceback (most recent call last)
Cell [0;32mIn [1], line 2[0m
[1;32m      1[0m [38;5;28;01mtry[39;00m:
[0;32m----> 2[0m     [38;5;28;01mimport[39;00m [38;5;21;01mdynamax[39;00m
[1;32m      3[0m [38;5;28;01mexcept[39;00m [38;5;167;01mModuleNotFoundError[39;00m:

[0;31mModuleNotFoundError[0m: No module named 'dynamax'

During handling of the above exception, another exception occurred:

[0;31mModuleNotFoundError[0m                       Traceback (most recent call last)
Cell [0;32mIn [1], line 6[0m
[1;32m      4[0m [38;5;28mprint[39m([38;5;124m'[39m[38;5;124minstalling dynamax[39m[38;5;124m'[39m)
[1;32m      5[0m get_ipython()[38;5;241m.[39mrun_line_magic([38;5;124m'[39m[38;5;124mpip[39m[38;5;124m'[39m, [38;5;124m'[39m[38;5;124minstall -qq dynamax[39m[38;5;124m'[39m)
[0;32m----> 6[0m [38;5;28;01mimport[39;00m [38;5;21;01mdynamax[39;00m

[0;31mModuleNotFoundError[0m: No module named 'dynamax'
ModuleNotFoundError: No module named 'dynamax'

